Workbook

Sheet HERITAGE 
A1: CONDO RESORT HERITAGE
A2: PROYECTO OPERADOR ÚnICO
A3: Proyección P&G Anual — 3 Años / 3 Escenarios (COP)
A5: DATOS GENERALES
A6: Unidades productivas Apartamentos 1 Habitacion | B6: 72
A7: Unidades productivas Apartamentos 2 Habitacion | B7: 36
A8: Días operación / año | B8: 365
A9: Crecimiento tarifa anual (ADR) | B9: 0.05
A10: Inflación costos fijos | B10: 0.05
A11: Factor prestacional nómina | B11: 1.45
A13: DETALLE - VARIABLES OPERATIVAS | B13: BASE MENSUAL | C13: PESIMISTA | F13: CONSERVADOR | I13: OPTIMISTA
C14: Año 1 | D14: Año 2 | E14: Año 3 | F14: Año 1 | G14: Año 2 | H14: Año 3 | I14: Año 1 | J14: Año 2 | K14: Año 3
A16: % Ocupación | C16: 0.35 | D16: 0.4 | E16: 0.45 | F16: 0.5 | G16: 0.55 | H16: 0.6 | I16: 0.65 | J16: 0.7 | K16: 0.75
A17: ADR (Tarifa promedio) 1 Habitacion | C17: 480000 | D17: =C17*(1+$B$9) -> 504000 | E17: =D17*(1+$B$9) -> 529200 | F17: =+C17*1.1 -> 528000 | G17: =F17*(1+$B$9) -> 554400 | H17: =G17*(1+$B$9) -> 582120 | I17: =F17*1.2 -> 633600 | J17: =I17*(1+$B$9) -> 665280 | K17: =J17*(1+$B$9) -> 698544
A18: ADR (Tarifa promedio) 2 Habitacion | C18: 550000 | D18: =C18*(1+$B$9) -> 577500 | E18: =D18*(1+$B$9) -> 606375 | F18: =+C18*1.1 -> 605000 | G18: =F18*(1+$B$9) -> 635250 | H18: =G18*(1+$B$9) -> 667012.5 | I18: =F18*1.2 -> 726000 | J18: =I18*(1+$B$9) -> 762300 | K18: =J18*(1+$B$9) -> 800415
A19: Unidades productivas Apartamentos 1 Habitacion | C19: =$B$6 -> 72 | D19: =$B$6 -> 72 | E19: =$B$6 -> 72 | F19: =$B$6 -> 72 | G19: =$B$6 -> 72 | H19: =$B$6 -> 72 | I19: =$B$6 -> 72 | J19: =$B$6 -> 72 | K19: =$B$6 -> 72
A20: Unidades productivas Apartamentos 2 Habitacion | C20: =$B$7 -> 36 | D20: =$B$7 -> 36 | E20: =$B$7 -> 36 | F20: =$B$7 -> 36 | G20: =$B$7 -> 36 | H20: =$B$7 -> 36 | I20: =$B$7 -> 36 | J20: =$B$7 -> 36 | K20: =$B$7 -> 36
A21: Días proyectados | C21: 350 | D21: 350 | E21: 350 | F21: 350 | G21: 350 | H21: 350 | I21: 350 | J21: 350 | K21: 350
A23: INGRESOS PROYECTADOS
A24: Ventas de hospedajes Apartamentos 1 Habitacion | C24: =C19*C17*C16*C21 -> 4233600000 | D24: =D19*D17*D16*D21 -> 5080320000 | E24: =E19*E17*E16*E21 -> 6001128000 | F24: =F19*F17*F16*F21 -> 6652800000 | G24: =G19*G17*G16*G21 -> 7683984000 | H24: =H19*H17*H16*H21 -> 8801654400 | I24: =I19*I17*I16*I21 -> 10378368000 | J24: =J19*J17*J16*J21 -> 1.1735539e+10 | K24: =K19*K17*K16*K21 -> 13202481600
A25: Ventas de hospedajes Apartamentos 2 Habitacion | C25: =C20*C18*C16*C21 -> 2425500000 | D25: =D20*D18*D16*D21 -> 2910600000 | E25: =E20*E18*E16*E21 -> 3438146250 | F25: =F20*F18*F16*F21 -> 3811500000 | G25: =G20*G18*G16*G21 -> 4.4022825e+09 | H25: =H20*H18*H16*H21 -> 5042614500 | I25: =I20*I18*I16*I21 -> 5945940000 | J25: =J20*J18*J16*J21 -> 6723486000 | K25: =K20*K18*K16*K21 -> 7563921750
A26: TOTAL INGRESOS | C26: =C24+C25 -> 6659100000 | D26: =D24+D25 -> 7990920000 | E26: =E24+E25 -> 9439274250 | F26: =F24+F25 -> 10464300000 | G26: =G24+G25 -> 12086266500 | H26: =H24+H25 -> 13844268900 | I26: =I24+I25 -> 16324308000 | J26: =J24+J25 -> 18459025200 | K26: =K24+K25 -> 20766403350
A28: GASTOS PROYECTADOS
A29: GASTOS NOMINA | B29: =D97 -> 100195000 | C29: =$B29*12 -> 1202340000 | D29: =C29*(1+$B$10) -> 1262457000 | E29: =D29*(1+$B$10) -> 1325579850 | F29: =$B29*12 -> 1202340000 | G29: =F29*(1+$B$10) -> 1262457000 | H29: =G29*(1+$B$10) -> 1325579850 | I29: =$B29*12 -> 1202340000 | J29: =I29*(1+$B$10) -> 1262457000 | K29: =J29*(1+$B$10) -> 1325579850
A30: Bolsa de Empleo | B30: 0.1 | C30: =+C29*$B$30 -> 120234000 | D30: =+D29*$B$30 -> 126245700 | E30: =+E29*$B$30 -> 132557985 | F30: =+F29*$B$30 -> 120234000 | G30: =+G29*$B$30 -> 126245700 | H30: =+H29*$B$30 -> 132557985 | I30: =+I29*$B$30 -> 120234000 | J30: =+J29*$B$30 -> 126245700 | K30: =+K29*$B$30 -> 132557985
A31: SERVICIOS PUBLICOS | C31: =SUM(C32:C35) -> 492000000 | D31: =SUM(D32:D35) -> 516600000 | E31: =SUM(E32:E35) -> 542430000 | F31: =SUM(F32:F35) -> 492000000 | G31: =SUM(G32:G35) -> 516600000 | H31: =SUM(H32:H35) -> 542430000 | I31: =SUM(I32:I35) -> 492000000 | J31: =SUM(J32:J35) -> 516600000 | K31: =SUM(K32:K35) -> 542430000
A32: Energía | B32: 25000000 | C32: =$B32*12 -> 300000000 | D32: =C32*(1+$B$10) -> 315000000 | E32: =D32*(1+$B$10) -> 330750000 | F32: =$B32*12 -> 300000000 | G32: =F32*(1+$B$10) -> 315000000 | H32: =G32*(1+$B$10) -> 330750000 | I32: =$B32*12 -> 300000000 | J32: =I32*(1+$B$10) -> 315000000 | K32: =J32*(1+$B$10) -> 330750000
A33: Agua | B33: 10000000 | C33: =$B33*12 -> 120000000 | D33: =C33*(1+$B$10) -> 126000000 | E33: =D33*(1+$B$10) -> 132300000 | F33: =$B33*12 -> 120000000 | G33: =F33*(1+$B$10) -> 126000000 | H33: =G33*(1+$B$10) -> 132300000 | I33: =$B33*12 -> 120000000 | J33: =I33*(1+$B$10) -> 126000000 | K33: =J33*(1+$B$10) -> 132300000
A34: Gas | B34: 3000000 | C34: =$B34*12 -> 36000000 | D34: =C34*(1+$B$10) -> 37800000 | E34: =D34*(1+$B$10) -> 39690000 | F34: =$B34*12 -> 36000000 | G34: =F34*(1+$B$10) -> 37800000 | H34: =G34*(1+$B$10) -> 39690000 | I34: =$B34*12 -> 36000000 | J34: =I34*(1+$B$10) -> 37800000 | K34: =J34*(1+$B$10) -> 39690000
A35: Internet / Cable / Telefonía | B35: 3000000 | C35: =$B35*12 -> 36000000 | D35: =C35*(1+$B$10) -> 37800000 | E35: =D35*(1+$B$10) -> 39690000 | F35: =$B35*12 -> 36000000 | G35: =F35*(1+$B$10) -> 37800000 | H35: =G35*(1+$B$10) -> 39690000 | I35: =$B35*12 -> 36000000 | J35: =I35*(1+$B$10) -> 37800000 | K35: =J35*(1+$B$10) -> 39690000
A37: TECNOLOGÍA Y COMUNICACIONES | C37: =SUM(C38:C40) -> 72000000 | D37: =SUM(D38:D40) -> 75600000 | E37: =SUM(E38:E40) -> 79380000 | F37: =SUM(F38:F40) -> 72000000 | G37: =SUM(G38:G40) -> 75600000 | H37: =SUM(H38:H40) -> 79380000 | I37: =SUM(I38:I40) -> 72000000 | J37: =SUM(J38:J40) -> 75600000 | K37: =SUM(K38:K40) -> 79380000
A38: PMS | B38: 4000000 | C38: =$B38*12 -> 48000000 | D38: =C38*(1+$B$10) -> 50400000 | E38: =D38*(1+$B$10) -> 52920000 | F38: =$B38*12 -> 48000000 | G38: =F38*(1+$B$10) -> 50400000 | H38: =G38*(1+$B$10) -> 52920000 | I38: =$B38*12 -> 48000000 | J38: =I38*(1+$B$10) -> 50400000 | K38: =J38*(1+$B$10) -> 52920000
A39: Channel Manager | B39: 2000000 | C39: =$B39*12 -> 24000000 | D39: =C39*(1+$B$10) -> 25200000 | E39: =D39*(1+$B$10) -> 26460000 | F39: =$B39*12 -> 24000000 | G39: =F39*(1+$B$10) -> 25200000 | H39: =G39*(1+$B$10) -> 26460000 | I39: =$B39*12 -> 24000000 | J39: =I39*(1+$B$10) -> 25200000 | K39: =J39*(1+$B$10) -> 26460000
A40: Revenue Management System ( Incluido en Feet Smart Stay ) | B40: 0 | C40: =$B40*12 -> 0 | D40: =C40*(1+$B$10) -> 0 | E40: =D40*(1+$B$10) -> 0 | F40: =$B40*12 -> 0 | G40: =F40*(1+$B$10) -> 0 | H40: =G40*(1+$B$10) -> 0 | I40: =$B40*12 -> 0 | J40: =I40*(1+$B$10) -> 0 | K40: =J40*(1+$B$10) -> 0
A41: CRM ( Incluido en Feet Smart Stay ) | B41: 0 | C41: =$B41*12 -> 0 | D41: =C41*(1+$B$10) -> 0 | E41: =D41*(1+$B$10) -> 0 | F41: =$B41*12 -> 0 | G41: =F41*(1+$B$10) -> 0 | H41: =G41*(1+$B$10) -> 0 | I41: =$B41*12 -> 0 | J41: =I41*(1+$B$10) -> 0 | K41: =J41*(1+$B$10) -> 0
A42: Automatizacion Cobros ( Incluido en Feet Smart Stay ) | B42: 0 | C42: =$B42*12 -> 0 | D42: =C42*(1+$B$10) -> 0 | E42: =D42*(1+$B$10) -> 0 | F42: =$B42*12 -> 0 | G42: =F42*(1+$B$10) -> 0 | H42: =G42*(1+$B$10) -> 0 | I42: =$B42*12 -> 0 | J42: =I42*(1+$B$10) -> 0 | K42: =J42*(1+$B$10) -> 0
A43: Sistemas de Mensajerias ( Incluido en Feet Smart Stay ) | B43: 0 | C43: =$B43*12 -> 0 | D43: =C43*(1+$B$10) -> 0 | E43: =D43*(1+$B$10) -> 0 | F43: =$B43*12 -> 0 | G43: =F43*(1+$B$10) -> 0 | H43: =G43*(1+$B$10) -> 0 | I43: =$B43*12 -> 0 | J43: =I43*(1+$B$10) -> 0 | K43: =J43*(1+$B$10) -> 0
A44: Ferias Nacional Anatos e Internacionales Fitur ( Incluido en Feet Smart Stay ) | B44: 0 | C44: =$B44*12 -> 0 | D44: =C44*(1+$B$10) -> 0 | E44: =D44*(1+$B$10) -> 0 | F44: =$B44*12 -> 0 | G44: =F44*(1+$B$10) -> 0 | H44: =G44*(1+$B$10) -> 0 | I44: =$B44*12 -> 0 | J44: =I44*(1+$B$10) -> 0 | K44: =J44*(1+$B$10) -> 0
A45: Chat Bot ( Incluido en Feet Smart Stay ) | B45: 0 | C45: =$B45*12 -> 0 | D45: =C45*(1+$B$10) -> 0 | E45: =D45*(1+$B$10) -> 0 | F45: =$B45*12 -> 0 | G45: =F45*(1+$B$10) -> 0 | H45: =G45*(1+$B$10) -> 0 | I45: =$B45*12 -> 0 | J45: =I45*(1+$B$10) -> 0 | K45: =J45*(1+$B$10) -> 0
A46: OPERACIÓN Y SUMINISTROS | C46: =SUM(C47:C50) -> 396000000 | D46: =SUM(D47:D50) -> 415800000 | E46: =SUM(E47:E50) -> 436590000 | F46: =SUM(F47:F50) -> 396000000 | G46: =SUM(G47:G50) -> 415800000 | H46: =SUM(H47:H50) -> 436590000 | I46: =SUM(I47:I50) -> 396000000 | J46: =SUM(J47:J50) -> 415800000 | K46: =SUM(K47:K50) -> 436590000
...

Sheet FARA Inv. Virtual
A1: CONDO RESORT HERITAGE
A2: FONDO FARA — INVERSIÓN VIRTUAL CON RENTABILIDAD 9% E.A.
A3: El FARA (3,5% de ventas) se destina a daños/mantto/reparaciones; mientras no se usa, se invierte y genera rendimiento distribuible entre propietarios
A5: PARÁMETROS DEL FONDO
A6: Tasa de rentabilidad anual (E.A.) | B6: 0.09
A7: N° de propietarios | B7: 108
A8: Crecimiento aporte Año 4-5 | B8: 0.08
A9: Convención: rendimiento de medio año sobre el aporte del periodo (mid-year)
A11: ESCENARIO PESIMISTA
A12: Concepto | B12: Año 1 | C12: Año 2 | D12: Año 3 | E12: Año 4 | F12: Año 5
A13: Aporte FARA (3% ventas) | B13: =+'HERITAGE '!C57 -> 199773000 | C13: =+'HERITAGE '!D57 -> 239727600 | D13: =+'HERITAGE '!E57 -> 2.8317823e+08 | E13: =D13*(1+$B$8) -> 3.0583249e+08 | F13: =E13*(1+$B$8) -> 3.3029908e+08
A14: Saldo inicial | B14: 0 | C14: =B16 -> 208762785 | D14: =C16 -> 4.7806678e+08 | E14: =D16 -> 8.1701404e+08 | F14: =E16 -> 1.2101402e+09
A15: Rendimiento (9% E.A.) | B15: =(B14+B13*0.5)*$B$6 -> 8989785 | C15: =(C14+C13*0.5)*$B$6 -> 29576393 | D15: =(D14+D13*0.5)*$B$6 -> 55769030 | E15: =(E14+E13*0.5)*$B$6 -> 87293725 | F15: =(F14+F13*0.5)*$B$6 -> 1.2377608e+08
A16: Saldo final del fondo | B16: =B14+B13+B15 -> 208762785 | C16: =C14+C13+C15 -> 4.7806678e+08 | D16: =D14+D13+D15 -> 8.1701404e+08 | E16: =E14+E13+E15 -> 1.2101402e+09 | F16: =F14+F13+F15 -> 1.6642154e+09
A17: Rendimiento por propietario | B17: =B15/$B$7 -> 83238.75 | C17: =C15/$B$7 -> 273855.49 | D17: =D15/$B$7 -> 516379.91 | E17: =E15/$B$7 -> 808275.23 | F17: =F15/$B$7 -> 1146074.8
A18: Saldo acumulado por propietario | B18: =B16/$B$7 -> 1932988.8 | C18: =C16/$B$7 -> 4426544.2 | D18: =D16/$B$7 -> 7564944.8 | E18: =E16/$B$7 -> 11205002 | F18: =F16/$B$7 -> 15409402
A21: ESCENARIO CONSERVADOR (ESPERADO)
A22: Concepto | B22: Año 1 | C22: Año 2 | D22: Año 3 | E22: Año 4 | F22: Año 5
A23: Aporte FARA (3% ventas) | B23: =+'HERITAGE '!F57 -> 313929000 | C23: =+'HERITAGE '!G57 -> 362587995 | D23: =+'HERITAGE '!H57 -> 415328067 | E23: =D23*(1+$B$8) -> 4.4855431e+08 | F23: =E23*(1+$B$8) -> 4.8443866e+08
A24: Saldo inicial | B24: 0 | C24: =B26 -> 328055805 | D24: =C26 -> 7.3648528e+08 | E24: =D26 -> 1.2367868e+09 | F24: =E26 -> 1.8168369e+09
A25: Rendimiento (9% E.A.) | B25: =(B24+B23*0.5)*$B$6 -> 14126805 | C25: =(C24+C23*0.5)*$B$6 -> 45841482 | D25: =(D24+D23*0.5)*$B$6 -> 84973438 | E25: =(E24+E23*0.5)*$B$6 -> 1.3149575e+08 | F25: =(F24+F23*0.5)*$B$6 -> 1.8531506e+08
A26: Saldo final del fondo | B26: =B24+B23+B25 -> 328055805 | C26: =C24+C23+C25 -> 7.3648528e+08 | D26: =D24+D23+D25 -> 1.2367868e+09 | E26: =E24+E23+E25 -> 1.8168369e+09 | F26: =F24+F23+F25 -> 2.4865906e+09
A27: Rendimiento por propietario | B27: =B25/$B$7 -> 130803.75 | C27: =C25/$B$7 -> 424458.17 | D27: =D25/$B$7 -> 786791.1 | E27: =E25/$B$7 -> 1217553.3 | F27: =F25/$B$7 -> 1715880.2
A28: Saldo acumulado por propietario | B28: =B26/$B$7 -> 3037553.8 | C28: =C26/$B$7 -> 6819308.2 | D28: =D26/$B$7 -> 11451730 | E28: =E26/$B$7 -> 16822563 | F28: =F26/$B$7 -> 23023987
A31: ESCENARIO OPTIMISTA
A32: Concepto | B32: Año 1 | C32: Año 2 | D32: Año 3 | E32: Año 4 | F32: Año 5
A33: Aporte FARA (3% ventas) | B33: =+'HERITAGE '!I57 -> 489729240 | C33: =+'HERITAGE '!J57 -> 553770756 | D33: =+'HERITAGE '!K57 -> 6.229921e+08 | E33: =D33*(1+$B$8) -> 6.7283147e+08 | F33: =E33*(1+$B$8) -> 7.2665799e+08
A34: Saldo inicial | B34: 0 | C34: =B36 -> 5.1176706e+08 | D34: =C36 -> 1.1365165e+09 | E34: =D36 -> 1.8898298e+09 | F34: =E36 -> 2.7630233e+09
A35: Rendimiento (9% E.A.) | B35: =(B34+B33*0.5)*$B$6 -> 22037816 | C35: =(C34+C33*0.5)*$B$6 -> 70978719 | D35: =(D34+D33*0.5)*$B$6 -> 1.3032113e+08 | E35: =(E34+E33*0.5)*$B$6 -> 2.0036209e+08 | F35: =(F34+F33*0.5)*$B$6 -> 2.8137171e+08
A36: Saldo final del fondo | B36: =B34+B33+B35 -> 5.1176706e+08 | C36: =C34+C33+C35 -> 1.1365165e+09 | D36: =D34+D33+D35 -> 1.8898298e+09 | E36: =E34+E33+E35 -> 2.7630233e+09 | F36: =F34+F33+F35 -> 3.771053e+09
A37: Rendimiento por propietario | B37: =B35/$B$7 -> 204053.85 | C37: =C35/$B$7 -> 657210.36 | D37: =D35/$B$7 -> 1206677.2 | E37: =E35/$B$7 -> 1855204.6 | F37: =F35/$B$7 -> 2605293.6
A38: Saldo acumulado por propietario | B38: =B36/$B$7 -> 4738583.9 | C38: =C36/$B$7 -> 10523301 | D38: =D36/$B$7 -> 17498424 | E38: =E36/$B$7 -> 25583549 | F38: =F36/$B$7 -> 34917158

Sheet Dashboard BI
A1: CONDO RESORT HERITAGE — TABLERO (BI)
A2: Indicadores por fórmula desde el modelo P&G (3 escenarios)
A4: 1. Comparativo Año 3 (maduración)
A5: Escenario | B5: Ingresos | C5: Gastos | D5: Utilidad Neta
A6: Pesimista | B6: =+'HERITAGE '!E26 -> 9439274250 | C6: =+'HERITAGE '!E65 -> 7900373880 | D6: =+'HERITAGE '!E71 -> 1.0002852e+09
A7: Conservador | B7: =+'HERITAGE '!H26 -> 13844268900 | C7: =+'HERITAGE '!H65 -> 9398072061 | D7: =+'HERITAGE '!H71 -> 2.8900279e+09
A8: Optimista | B8: =+'HERITAGE '!K26 -> 20766403350 | C8: =+'HERITAGE '!K65 -> 11751597774 | D8: =+'HERITAGE '!K71 -> 5.8596236e+09
A11: 2. Utilidad Neta por Año (COP)
A12: Año | B12: Pesimista | C12: Conservador | D12: Optimista
A13: Año 1 | B13: =+'HERITAGE '!C71 -> 91072800 | C13: =+'HERITAGE '!F71 -> 1723503600 | D13: =+'HERITAGE '!I71 -> 4237447032
A14: Año 2 | B14: =+'HERITAGE '!D71 -> 524139525 | C14: =+'HERITAGE '!G71 -> 2.2810432e+09 | D14: =+'HERITAGE '!J71 -> 5.0149567e+09
A15: Año 3 | B15: =+'HERITAGE '!E71 -> 1.0002852e+09 | C15: =+'HERITAGE '!H71 -> 2.8900279e+09 | D15: =+'HERITAGE '!K71 -> 5.8596236e+09
A18: 3. Estructura de Costos (Conservador Año 3)
A19: Categoría | B19: Valor anual
A20: Nómina operativa | B20: =+'HERITAGE '!H29 -> 1325579850
A21: Servicios públicos | B21: =+'HERITAGE '!H31 -> 542430000
A22: Tecnología y comunicaciones | B22: =+'HERITAGE '!H37 -> 79380000
A23: Operación y suministros | B23: =+'HERITAGE '!H46 -> 436590000
A24: Marketing | B24: =+'HERITAGE '!H51 -> 138442689
A25: Domótica | B25: =+'HERITAGE '!H52 -> 0
A26: Administración / condominio | B26: =+'HERITAGE '!H53 -> 714420000
A27: Seguros y licencias | B27: =+'HERITAGE '!H54+'HERITAGE '!H59 -> 304290000
A28: Contable + Revisoría fiscal | B28: =+'HERITAGE '!H55+'HERITAGE '!H56 -> 132300000
A29: FARA (inversión virtual) | B29: =+'HERITAGE '!H57 -> 415328067
A30: Otros gastos operativos | B30: =+'HERITAGE '!H58 -> 423360000
A31: Comisiones OTAs | B31: =+'HERITAGE '!H62 -> 2491968402
A32: Honorarios operación (fee) | B32: =+'HERITAGE '!H63+'HERITAGE '!H64 -> 2261425068
A36: 4. Utilidad Neta por unidad — Año 3 (1-Hab vs 2-Hab)
A37: Escenario | B37: Por unidad 1-Hab | C37: Por unidad 2-Hab
A38: Pesimista | B38: =+'HERITAGE '!E71*('HERITAGE '!E24/'HERITAGE '!E26)/'HERITAGE '!$B$6 -> 8832540.8 | C38: =+'HERITAGE '!E71*('HERITAGE '!E25/'HERITAGE '!E26)/'HERITAGE '!$B$7 -> 10120620
A39: Conservador | B39: =+'HERITAGE '!H71*('HERITAGE '!H24/'HERITAGE '!H26)/'HERITAGE '!$B$6 -> 25519011 | C39: =+'HERITAGE '!H71*('HERITAGE '!H25/'HERITAGE '!H26)/'HERITAGE '!$B$7 -> 29240533
A40: Optimista | B40: =+'HERITAGE '!K71*('HERITAGE '!K24/'HERITAGE '!K26)/'HERITAGE '!$B$6 -> 51740606 | C40: =+'HERITAGE '!K71*('HERITAGE '!K25/'HERITAGE '!K26)/'HERITAGE '!$B$7 -> 59286111

Sheet Reparto por Pool
A1: CONDO RESORT HERITAGE
A2: REPARTO DE UTILIDADES POR POOL DE HABITACIONES
A3: Cada pool recauda los ingresos de su tipología; los gastos se asignan proporcionalmente a esos ingresos. La participación se calcula con las ventas reales (filas 25/26 de HERITAGE).
A5: 1. Estado de Resultados por POOL — Conservador, Año 3 (maduración)
A6: Concepto | B6: Pool 1-Hab | C6: Pool 2-Hab | D6: TOTAL
A7: Ingresos del pool | B7: =+'HERITAGE '!H24 -> 8801654400 | C7: =+'HERITAGE '!H25 -> 5042614500 | D7: =+'HERITAGE '!H26 -> 13844268900
A8: % de ingresos (criterio de reparto) | B8: =B7/$D$7 -> 0.63576159 | C8: =C7/$D$7 -> 0.36423841 | D8: =B8+C8 -> 1
A9: (−) Costos, gastos e impuesto asignados | B9: =-(B7-'HERITAGE '!H71*B8) -> -6.9642856e+09 | C9: =-(C7-'HERITAGE '!H71*C8) -> -3.9899553e+09 | D9: =B9+C9 -> -1.0954241e+10
A10: Utilidad neta del pool | B10: =B7+B9 -> 1.8373688e+09 | C10: =C7+C9 -> 1.0526592e+09 | D10: =+'HERITAGE '!H71 -> 2.8900279e+09
A11: Margen neto | B11: =B10/B7 -> 0.20875266 | C11: =C10/C7 -> 0.20875266 | D11: =D10/D7 -> 0.20875266
A12: N° de unidades | B12: =+'HERITAGE '!$B$6 -> 72 | C12: =+'HERITAGE '!$B$7 -> 36 | D12: =B12+C12 -> 108
A13: Utilidad por unidad / año | B13: =B10/B12 -> 25519011 | C13: =C10/C12 -> 29240533 | D13: =D10/D12 -> 26759518
A15: 2. Utilidad neta por unidad — Año 3 (maduración)
A16: Escenario | B16: Util. Pool 1-Hab | C16: Util. Pool 2-Hab | D16: Por unidad 1-Hab | E16: Por unidad 2-Hab
A17: Pesimista | B17: =+'HERITAGE '!E71*('HERITAGE '!E24/'HERITAGE '!E26) -> 6.3594293e+08 | C17: =+'HERITAGE '!E71*('HERITAGE '!E25/'HERITAGE '!E26) -> 3.6434231e+08 | D17: =B17/'HERITAGE '!$B$6 -> 8832540.8 | E17: =C17/'HERITAGE '!$B$7 -> 10120620
A18: Conservador | B18: =+'HERITAGE '!H71*('HERITAGE '!H24/'HERITAGE '!H26) -> 1.8373688e+09 | C18: =+'HERITAGE '!H71*('HERITAGE '!H25/'HERITAGE '!H26) -> 1.0526592e+09 | D18: =B18/'HERITAGE '!$B$6 -> 25519011 | E18: =C18/'HERITAGE '!$B$7 -> 29240533
A19: Optimista | B19: =+'HERITAGE '!K71*('HERITAGE '!K24/'HERITAGE '!K26) -> 3.7253236e+09 | C19: =+'HERITAGE '!K71*('HERITAGE '!K25/'HERITAGE '!K26) -> 2.1343e+09 | D19: =B19/'HERITAGE '!$B$6 -> 51740606 | E19: =C19/'HERITAGE '!$B$7 -> 59286111

Sheet Hoja1
A1: 1-termina el esquema según el tipo de unidad 72 de 1 una habitacion y 36 de 2 habitaciones
A2: 2-el fara lo lleves a un ahorro virtual con rendimiento a una tasa del 9% y que este a la vez según lo esperado vaya proyectando en rendimiento
A3: 3- de acuerdo a tu experiencia en experto financiero aprovecha tus conocimientos en herramientas de bisnes inteligent y realiza la modelacion de los graficos para interpretar los datos del excel de la mejor forma
A4: 4- firma de contadores y revisoria fiscal me puedes modelar y cuantas personas se pueden estar neceitando para un modelo como heritage
A5: 5- Persona de calidad y seguridad salu en el trabajo
A9: Gastos de flores y decoracion
A10: servicios de minibar
A11: gastos medicos
A12: bonificaciones
A13: sericios de ambulancia
A14: alimentacion de empleados
A15: licencias
... A20: Ambientadores

Sheet Hoja2
